# This shows what happens when a function throws an unhandled exception.

def innocent_fn():
    say_hello('Bob')

def main():
    innocent_fn()
